2025-01-13 16:33:03 [scheduling-1] ERROR p.e.domain.test.testService - testests
2025-01-13 16:33:13 [scheduling-1] ERROR p.e.domain.test.testService - testests
2025-01-13 16:33:23 [scheduling-1] ERROR p.e.domain.test.testService - testests
2025-01-13 16:33:33 [scheduling-1] ERROR p.e.domain.test.testService - testests
2025-01-13 16:33:43 [scheduling-1] ERROR p.e.domain.test.testService - testests
2025-01-13 17:15:20 [scheduling-1] ERROR p.e.domain.test.testService - test
2025-01-13 17:15:20 [scheduling-1] ERROR o.s.s.s.TaskUtils$LoggingErrorHandler - Unexpected error occurred in scheduled task
practice.error_exception.global.exception.object.ServiceException: TEST
	at practice.error_exception.domain.test.testService.logTest(testService.java:17)
	at java.base/jdk.internal.reflect.NativeMethodAccessorImpl.invoke0(Native Method)
	at java.base/jdk.internal.reflect.NativeMethodAccessorImpl.invoke(NativeMethodAccessorImpl.java:77)
	at java.base/jdk.internal.reflect.DelegatingMethodAccessorImpl.invoke(DelegatingMethodAccessorImpl.java:43)
	at java.base/java.lang.reflect.Method.invoke(Method.java:568)
	at org.springframework.scheduling.support.ScheduledMethodRunnable.runInternal(ScheduledMethodRunnable.java:130)
	at org.springframework.scheduling.support.ScheduledMethodRunnable.lambda$run$2(ScheduledMethodRunnable.java:124)
	at io.micrometer.observation.Observation.observe(Observation.java:498)
	at org.springframework.scheduling.support.ScheduledMethodRunnable.run(ScheduledMethodRunnable.java:124)
	at org.springframework.scheduling.config.Task$OutcomeTrackingRunnable.run(Task.java:85)
	at org.springframework.scheduling.support.DelegatingErrorHandlingRunnable.run(DelegatingErrorHandlingRunnable.java:54)
	at java.base/java.util.concurrent.Executors$RunnableAdapter.call(Executors.java:539)
	at java.base/java.util.concurrent.FutureTask.runAndReset(FutureTask.java:305)
	at java.base/java.util.concurrent.ScheduledThreadPoolExecutor$ScheduledFutureTask.run(ScheduledThreadPoolExecutor.java:305)
	at java.base/java.util.concurrent.ThreadPoolExecutor.runWorker(ThreadPoolExecutor.java:1136)
	at java.base/java.util.concurrent.ThreadPoolExecutor$Worker.run(ThreadPoolExecutor.java:635)
	at java.base/java.lang.Thread.run(Thread.java:842)
2025-01-13 17:15:30 [scheduling-1] ERROR p.e.domain.test.testService - test
2025-01-13 17:15:30 [scheduling-1] ERROR o.s.s.s.TaskUtils$LoggingErrorHandler - Unexpected error occurred in scheduled task
practice.error_exception.global.exception.object.ServiceException: TEST
	at practice.error_exception.domain.test.testService.logTest(testService.java:17)
	at java.base/jdk.internal.reflect.NativeMethodAccessorImpl.invoke0(Native Method)
	at java.base/jdk.internal.reflect.NativeMethodAccessorImpl.invoke(NativeMethodAccessorImpl.java:77)
	at java.base/jdk.internal.reflect.DelegatingMethodAccessorImpl.invoke(DelegatingMethodAccessorImpl.java:43)
	at java.base/java.lang.reflect.Method.invoke(Method.java:568)
	at org.springframework.scheduling.support.ScheduledMethodRunnable.runInternal(ScheduledMethodRunnable.java:130)
	at org.springframework.scheduling.support.ScheduledMethodRunnable.lambda$run$2(ScheduledMethodRunnable.java:124)
	at io.micrometer.observation.Observation.observe(Observation.java:498)
	at org.springframework.scheduling.support.ScheduledMethodRunnable.run(ScheduledMethodRunnable.java:124)
	at org.springframework.scheduling.config.Task$OutcomeTrackingRunnable.run(Task.java:85)
	at org.springframework.scheduling.support.DelegatingErrorHandlingRunnable.run(DelegatingErrorHandlingRunnable.java:54)
	at java.base/java.util.concurrent.Executors$RunnableAdapter.call(Executors.java:539)
	at java.base/java.util.concurrent.FutureTask.runAndReset(FutureTask.java:305)
	at java.base/java.util.concurrent.ScheduledThreadPoolExecutor$ScheduledFutureTask.run(ScheduledThreadPoolExecutor.java:305)
	at java.base/java.util.concurrent.ThreadPoolExecutor.runWorker(ThreadPoolExecutor.java:1136)
	at java.base/java.util.concurrent.ThreadPoolExecutor$Worker.run(ThreadPoolExecutor.java:635)
	at java.base/java.lang.Thread.run(Thread.java:842)
2025-01-13 17:15:40 [scheduling-1] ERROR p.e.domain.test.testService - test
2025-01-13 17:15:40 [scheduling-1] ERROR o.s.s.s.TaskUtils$LoggingErrorHandler - Unexpected error occurred in scheduled task
practice.error_exception.global.exception.object.ServiceException: TEST
	at practice.error_exception.domain.test.testService.logTest(testService.java:17)
	at java.base/jdk.internal.reflect.NativeMethodAccessorImpl.invoke0(Native Method)
	at java.base/jdk.internal.reflect.NativeMethodAccessorImpl.invoke(NativeMethodAccessorImpl.java:77)
	at java.base/jdk.internal.reflect.DelegatingMethodAccessorImpl.invoke(DelegatingMethodAccessorImpl.java:43)
	at java.base/java.lang.reflect.Method.invoke(Method.java:568)
	at org.springframework.scheduling.support.ScheduledMethodRunnable.runInternal(ScheduledMethodRunnable.java:130)
	at org.springframework.scheduling.support.ScheduledMethodRunnable.lambda$run$2(ScheduledMethodRunnable.java:124)
	at io.micrometer.observation.Observation.observe(Observation.java:498)
	at org.springframework.scheduling.support.ScheduledMethodRunnable.run(ScheduledMethodRunnable.java:124)
	at org.springframework.scheduling.config.Task$OutcomeTrackingRunnable.run(Task.java:85)
	at org.springframework.scheduling.support.DelegatingErrorHandlingRunnable.run(DelegatingErrorHandlingRunnable.java:54)
	at java.base/java.util.concurrent.Executors$RunnableAdapter.call(Executors.java:539)
	at java.base/java.util.concurrent.FutureTask.runAndReset(FutureTask.java:305)
	at java.base/java.util.concurrent.ScheduledThreadPoolExecutor$ScheduledFutureTask.run(ScheduledThreadPoolExecutor.java:305)
	at java.base/java.util.concurrent.ThreadPoolExecutor.runWorker(ThreadPoolExecutor.java:1136)
	at java.base/java.util.concurrent.ThreadPoolExecutor$Worker.run(ThreadPoolExecutor.java:635)
	at java.base/java.lang.Thread.run(Thread.java:842)
2025-01-13 17:15:50 [scheduling-1] ERROR p.e.domain.test.testService - test
2025-01-13 17:15:50 [scheduling-1] ERROR o.s.s.s.TaskUtils$LoggingErrorHandler - Unexpected error occurred in scheduled task
practice.error_exception.global.exception.object.ServiceException: TEST
	at practice.error_exception.domain.test.testService.logTest(testService.java:17)
	at java.base/jdk.internal.reflect.NativeMethodAccessorImpl.invoke0(Native Method)
	at java.base/jdk.internal.reflect.NativeMethodAccessorImpl.invoke(NativeMethodAccessorImpl.java:77)
	at java.base/jdk.internal.reflect.DelegatingMethodAccessorImpl.invoke(DelegatingMethodAccessorImpl.java:43)
	at java.base/java.lang.reflect.Method.invoke(Method.java:568)
	at org.springframework.scheduling.support.ScheduledMethodRunnable.runInternal(ScheduledMethodRunnable.java:130)
	at org.springframework.scheduling.support.ScheduledMethodRunnable.lambda$run$2(ScheduledMethodRunnable.java:124)
	at io.micrometer.observation.Observation.observe(Observation.java:498)
	at org.springframework.scheduling.support.ScheduledMethodRunnable.run(ScheduledMethodRunnable.java:124)
	at org.springframework.scheduling.config.Task$OutcomeTrackingRunnable.run(Task.java:85)
	at org.springframework.scheduling.support.DelegatingErrorHandlingRunnable.run(DelegatingErrorHandlingRunnable.java:54)
	at java.base/java.util.concurrent.Executors$RunnableAdapter.call(Executors.java:539)
	at java.base/java.util.concurrent.FutureTask.runAndReset(FutureTask.java:305)
	at java.base/java.util.concurrent.ScheduledThreadPoolExecutor$ScheduledFutureTask.run(ScheduledThreadPoolExecutor.java:305)
	at java.base/java.util.concurrent.ThreadPoolExecutor.runWorker(ThreadPoolExecutor.java:1136)
	at java.base/java.util.concurrent.ThreadPoolExecutor$Worker.run(ThreadPoolExecutor.java:635)
	at java.base/java.lang.Thread.run(Thread.java:842)
2025-01-13 17:17:55 [scheduling-1] ERROR p.e.domain.test.testService - test
2025-01-13 17:17:55 [scheduling-1] ERROR o.s.s.s.TaskUtils$LoggingErrorHandler - Unexpected error occurred in scheduled task
practice.error_exception.global.exception.object.ServiceException: TEST
	at practice.error_exception.domain.test.testService.logTest(testService.java:17)
	at java.base/jdk.internal.reflect.NativeMethodAccessorImpl.invoke0(Native Method)
	at java.base/jdk.internal.reflect.NativeMethodAccessorImpl.invoke(NativeMethodAccessorImpl.java:77)
	at java.base/jdk.internal.reflect.DelegatingMethodAccessorImpl.invoke(DelegatingMethodAccessorImpl.java:43)
	at java.base/java.lang.reflect.Method.invoke(Method.java:568)
	at org.springframework.scheduling.support.ScheduledMethodRunnable.runInternal(ScheduledMethodRunnable.java:130)
	at org.springframework.scheduling.support.ScheduledMethodRunnable.lambda$run$2(ScheduledMethodRunnable.java:124)
	at io.micrometer.observation.Observation.observe(Observation.java:498)
	at org.springframework.scheduling.support.ScheduledMethodRunnable.run(ScheduledMethodRunnable.java:124)
	at org.springframework.scheduling.config.Task$OutcomeTrackingRunnable.run(Task.java:85)
	at org.springframework.scheduling.support.DelegatingErrorHandlingRunnable.run(DelegatingErrorHandlingRunnable.java:54)
	at java.base/java.util.concurrent.Executors$RunnableAdapter.call(Executors.java:539)
	at java.base/java.util.concurrent.FutureTask.runAndReset(FutureTask.java:305)
	at java.base/java.util.concurrent.ScheduledThreadPoolExecutor$ScheduledFutureTask.run(ScheduledThreadPoolExecutor.java:305)
	at java.base/java.util.concurrent.ThreadPoolExecutor.runWorker(ThreadPoolExecutor.java:1136)
	at java.base/java.util.concurrent.ThreadPoolExecutor$Worker.run(ThreadPoolExecutor.java:635)
	at java.base/java.lang.Thread.run(Thread.java:842)
2025-01-13 17:18:05 [scheduling-1] ERROR p.e.domain.test.testService - test
2025-01-13 17:18:05 [scheduling-1] ERROR o.s.s.s.TaskUtils$LoggingErrorHandler - Unexpected error occurred in scheduled task
practice.error_exception.global.exception.object.ServiceException: TEST
	at practice.error_exception.domain.test.testService.logTest(testService.java:17)
	at java.base/jdk.internal.reflect.NativeMethodAccessorImpl.invoke0(Native Method)
	at java.base/jdk.internal.reflect.NativeMethodAccessorImpl.invoke(NativeMethodAccessorImpl.java:77)
	at java.base/jdk.internal.reflect.DelegatingMethodAccessorImpl.invoke(DelegatingMethodAccessorImpl.java:43)
	at java.base/java.lang.reflect.Method.invoke(Method.java:568)
	at org.springframework.scheduling.support.ScheduledMethodRunnable.runInternal(ScheduledMethodRunnable.java:130)
	at org.springframework.scheduling.support.ScheduledMethodRunnable.lambda$run$2(ScheduledMethodRunnable.java:124)
	at io.micrometer.observation.Observation.observe(Observation.java:498)
	at org.springframework.scheduling.support.ScheduledMethodRunnable.run(ScheduledMethodRunnable.java:124)
	at org.springframework.scheduling.config.Task$OutcomeTrackingRunnable.run(Task.java:85)
	at org.springframework.scheduling.support.DelegatingErrorHandlingRunnable.run(DelegatingErrorHandlingRunnable.java:54)
	at java.base/java.util.concurrent.Executors$RunnableAdapter.call(Executors.java:539)
	at java.base/java.util.concurrent.FutureTask.runAndReset(FutureTask.java:305)
	at java.base/java.util.concurrent.ScheduledThreadPoolExecutor$ScheduledFutureTask.run(ScheduledThreadPoolExecutor.java:305)
	at java.base/java.util.concurrent.ThreadPoolExecutor.runWorker(ThreadPoolExecutor.java:1136)
	at java.base/java.util.concurrent.ThreadPoolExecutor$Worker.run(ThreadPoolExecutor.java:635)
	at java.base/java.lang.Thread.run(Thread.java:842)
2025-01-13 17:19:05 [scheduling-1] ERROR p.e.domain.test.testService - test
2025-01-13 17:19:05 [scheduling-1] ERROR o.s.s.s.TaskUtils$LoggingErrorHandler - Unexpected error occurred in scheduled task
practice.error_exception.global.exception.object.ServiceException: TEST
	at practice.error_exception.domain.test.testService.logTest(testService.java:17)
	at java.base/jdk.internal.reflect.NativeMethodAccessorImpl.invoke0(Native Method)
	at java.base/jdk.internal.reflect.NativeMethodAccessorImpl.invoke(NativeMethodAccessorImpl.java:77)
	at java.base/jdk.internal.reflect.DelegatingMethodAccessorImpl.invoke(DelegatingMethodAccessorImpl.java:43)
	at java.base/java.lang.reflect.Method.invoke(Method.java:568)
	at org.springframework.scheduling.support.ScheduledMethodRunnable.runInternal(ScheduledMethodRunnable.java:130)
	at org.springframework.scheduling.support.ScheduledMethodRunnable.lambda$run$2(ScheduledMethodRunnable.java:124)
	at io.micrometer.observation.Observation.observe(Observation.java:498)
	at org.springframework.scheduling.support.ScheduledMethodRunnable.run(ScheduledMethodRunnable.java:124)
	at org.springframework.scheduling.config.Task$OutcomeTrackingRunnable.run(Task.java:85)
	at org.springframework.scheduling.support.DelegatingErrorHandlingRunnable.run(DelegatingErrorHandlingRunnable.java:54)
	at java.base/java.util.concurrent.Executors$RunnableAdapter.call(Executors.java:539)
	at java.base/java.util.concurrent.FutureTask.runAndReset(FutureTask.java:305)
	at java.base/java.util.concurrent.ScheduledThreadPoolExecutor$ScheduledFutureTask.run(ScheduledThreadPoolExecutor.java:305)
	at java.base/java.util.concurrent.ThreadPoolExecutor.runWorker(ThreadPoolExecutor.java:1136)
	at java.base/java.util.concurrent.ThreadPoolExecutor$Worker.run(ThreadPoolExecutor.java:635)
	at java.base/java.lang.Thread.run(Thread.java:842)
2025-01-13 17:19:15 [scheduling-1] ERROR p.e.domain.test.testService - test
2025-01-13 17:19:15 [scheduling-1] ERROR o.s.s.s.TaskUtils$LoggingErrorHandler - Unexpected error occurred in scheduled task
practice.error_exception.global.exception.object.ServiceException: TEST
	at practice.error_exception.domain.test.testService.logTest(testService.java:17)
	at java.base/jdk.internal.reflect.NativeMethodAccessorImpl.invoke0(Native Method)
	at java.base/jdk.internal.reflect.NativeMethodAccessorImpl.invoke(NativeMethodAccessorImpl.java:77)
	at java.base/jdk.internal.reflect.DelegatingMethodAccessorImpl.invoke(DelegatingMethodAccessorImpl.java:43)
	at java.base/java.lang.reflect.Method.invoke(Method.java:568)
	at org.springframework.scheduling.support.ScheduledMethodRunnable.runInternal(ScheduledMethodRunnable.java:130)
	at org.springframework.scheduling.support.ScheduledMethodRunnable.lambda$run$2(ScheduledMethodRunnable.java:124)
	at io.micrometer.observation.Observation.observe(Observation.java:498)
	at org.springframework.scheduling.support.ScheduledMethodRunnable.run(ScheduledMethodRunnable.java:124)
	at org.springframework.scheduling.config.Task$OutcomeTrackingRunnable.run(Task.java:85)
	at org.springframework.scheduling.support.DelegatingErrorHandlingRunnable.run(DelegatingErrorHandlingRunnable.java:54)
	at java.base/java.util.concurrent.Executors$RunnableAdapter.call(Executors.java:539)
	at java.base/java.util.concurrent.FutureTask.runAndReset(FutureTask.java:305)
	at java.base/java.util.concurrent.ScheduledThreadPoolExecutor$ScheduledFutureTask.run(ScheduledThreadPoolExecutor.java:305)
	at java.base/java.util.concurrent.ThreadPoolExecutor.runWorker(ThreadPoolExecutor.java:1136)
	at java.base/java.util.concurrent.ThreadPoolExecutor$Worker.run(ThreadPoolExecutor.java:635)
	at java.base/java.lang.Thread.run(Thread.java:842)
2025-01-13 17:19:25 [scheduling-1] ERROR p.e.domain.test.testService - test
2025-01-13 17:19:25 [scheduling-1] ERROR o.s.s.s.TaskUtils$LoggingErrorHandler - Unexpected error occurred in scheduled task
practice.error_exception.global.exception.object.ServiceException: TEST
	at practice.error_exception.domain.test.testService.logTest(testService.java:17)
	at java.base/jdk.internal.reflect.NativeMethodAccessorImpl.invoke0(Native Method)
	at java.base/jdk.internal.reflect.NativeMethodAccessorImpl.invoke(NativeMethodAccessorImpl.java:77)
	at java.base/jdk.internal.reflect.DelegatingMethodAccessorImpl.invoke(DelegatingMethodAccessorImpl.java:43)
	at java.base/java.lang.reflect.Method.invoke(Method.java:568)
	at org.springframework.scheduling.support.ScheduledMethodRunnable.runInternal(ScheduledMethodRunnable.java:130)
	at org.springframework.scheduling.support.ScheduledMethodRunnable.lambda$run$2(ScheduledMethodRunnable.java:124)
	at io.micrometer.observation.Observation.observe(Observation.java:498)
	at org.springframework.scheduling.support.ScheduledMethodRunnable.run(ScheduledMethodRunnable.java:124)
	at org.springframework.scheduling.config.Task$OutcomeTrackingRunnable.run(Task.java:85)
	at org.springframework.scheduling.support.DelegatingErrorHandlingRunnable.run(DelegatingErrorHandlingRunnable.java:54)
	at java.base/java.util.concurrent.Executors$RunnableAdapter.call(Executors.java:539)
	at java.base/java.util.concurrent.FutureTask.runAndReset(FutureTask.java:305)
	at java.base/java.util.concurrent.ScheduledThreadPoolExecutor$ScheduledFutureTask.run(ScheduledThreadPoolExecutor.java:305)
	at java.base/java.util.concurrent.ThreadPoolExecutor.runWorker(ThreadPoolExecutor.java:1136)
	at java.base/java.util.concurrent.ThreadPoolExecutor$Worker.run(ThreadPoolExecutor.java:635)
	at java.base/java.lang.Thread.run(Thread.java:842)
2025-01-13 17:19:35 [scheduling-1] ERROR p.e.domain.test.testService - test
2025-01-13 17:19:35 [scheduling-1] ERROR o.s.s.s.TaskUtils$LoggingErrorHandler - Unexpected error occurred in scheduled task
practice.error_exception.global.exception.object.ServiceException: TEST
	at practice.error_exception.domain.test.testService.logTest(testService.java:17)
	at java.base/jdk.internal.reflect.NativeMethodAccessorImpl.invoke0(Native Method)
	at java.base/jdk.internal.reflect.NativeMethodAccessorImpl.invoke(NativeMethodAccessorImpl.java:77)
	at java.base/jdk.internal.reflect.DelegatingMethodAccessorImpl.invoke(DelegatingMethodAccessorImpl.java:43)
	at java.base/java.lang.reflect.Method.invoke(Method.java:568)
	at org.springframework.scheduling.support.ScheduledMethodRunnable.runInternal(ScheduledMethodRunnable.java:130)
	at org.springframework.scheduling.support.ScheduledMethodRunnable.lambda$run$2(ScheduledMethodRunnable.java:124)
	at io.micrometer.observation.Observation.observe(Observation.java:498)
	at org.springframework.scheduling.support.ScheduledMethodRunnable.run(ScheduledMethodRunnable.java:124)
	at org.springframework.scheduling.config.Task$OutcomeTrackingRunnable.run(Task.java:85)
	at org.springframework.scheduling.support.DelegatingErrorHandlingRunnable.run(DelegatingErrorHandlingRunnable.java:54)
	at java.base/java.util.concurrent.Executors$RunnableAdapter.call(Executors.java:539)
	at java.base/java.util.concurrent.FutureTask.runAndReset(FutureTask.java:305)
	at java.base/java.util.concurrent.ScheduledThreadPoolExecutor$ScheduledFutureTask.run(ScheduledThreadPoolExecutor.java:305)
	at java.base/java.util.concurrent.ThreadPoolExecutor.runWorker(ThreadPoolExecutor.java:1136)
	at java.base/java.util.concurrent.ThreadPoolExecutor$Worker.run(ThreadPoolExecutor.java:635)
	at java.base/java.lang.Thread.run(Thread.java:842)
2025-01-13 17:19:45 [scheduling-1] ERROR p.e.domain.test.testService - test
2025-01-13 17:19:45 [scheduling-1] ERROR o.s.s.s.TaskUtils$LoggingErrorHandler - Unexpected error occurred in scheduled task
practice.error_exception.global.exception.object.ServiceException: TEST
	at practice.error_exception.domain.test.testService.logTest(testService.java:17)
	at java.base/jdk.internal.reflect.NativeMethodAccessorImpl.invoke0(Native Method)
	at java.base/jdk.internal.reflect.NativeMethodAccessorImpl.invoke(NativeMethodAccessorImpl.java:77)
	at java.base/jdk.internal.reflect.DelegatingMethodAccessorImpl.invoke(DelegatingMethodAccessorImpl.java:43)
	at java.base/java.lang.reflect.Method.invoke(Method.java:568)
	at org.springframework.scheduling.support.ScheduledMethodRunnable.runInternal(ScheduledMethodRunnable.java:130)
	at org.springframework.scheduling.support.ScheduledMethodRunnable.lambda$run$2(ScheduledMethodRunnable.java:124)
	at io.micrometer.observation.Observation.observe(Observation.java:498)
	at org.springframework.scheduling.support.ScheduledMethodRunnable.run(ScheduledMethodRunnable.java:124)
	at org.springframework.scheduling.config.Task$OutcomeTrackingRunnable.run(Task.java:85)
	at org.springframework.scheduling.support.DelegatingErrorHandlingRunnable.run(DelegatingErrorHandlingRunnable.java:54)
	at java.base/java.util.concurrent.Executors$RunnableAdapter.call(Executors.java:539)
	at java.base/java.util.concurrent.FutureTask.runAndReset(FutureTask.java:305)
	at java.base/java.util.concurrent.ScheduledThreadPoolExecutor$ScheduledFutureTask.run(ScheduledThreadPoolExecutor.java:305)
	at java.base/java.util.concurrent.ThreadPoolExecutor.runWorker(ThreadPoolExecutor.java:1136)
	at java.base/java.util.concurrent.ThreadPoolExecutor$Worker.run(ThreadPoolExecutor.java:635)
	at java.base/java.lang.Thread.run(Thread.java:842)
2025-01-13 17:20:41 [scheduling-1] ERROR p.e.domain.test.testService - test
2025-01-13 17:20:41 [scheduling-1] ERROR o.s.s.s.TaskUtils$LoggingErrorHandler - Unexpected error occurred in scheduled task
practice.error_exception.global.exception.object.ServiceException: TEST
	at practice.error_exception.domain.test.testService.logTest(testService.java:17)
	at java.base/jdk.internal.reflect.NativeMethodAccessorImpl.invoke0(Native Method)
	at java.base/jdk.internal.reflect.NativeMethodAccessorImpl.invoke(NativeMethodAccessorImpl.java:77)
	at java.base/jdk.internal.reflect.DelegatingMethodAccessorImpl.invoke(DelegatingMethodAccessorImpl.java:43)
	at java.base/java.lang.reflect.Method.invoke(Method.java:568)
	at org.springframework.scheduling.support.ScheduledMethodRunnable.runInternal(ScheduledMethodRunnable.java:130)
	at org.springframework.scheduling.support.ScheduledMethodRunnable.lambda$run$2(ScheduledMethodRunnable.java:124)
	at io.micrometer.observation.Observation.observe(Observation.java:498)
	at org.springframework.scheduling.support.ScheduledMethodRunnable.run(ScheduledMethodRunnable.java:124)
	at org.springframework.scheduling.config.Task$OutcomeTrackingRunnable.run(Task.java:85)
	at org.springframework.scheduling.support.DelegatingErrorHandlingRunnable.run(DelegatingErrorHandlingRunnable.java:54)
	at java.base/java.util.concurrent.Executors$RunnableAdapter.call(Executors.java:539)
	at java.base/java.util.concurrent.FutureTask.runAndReset(FutureTask.java:305)
	at java.base/java.util.concurrent.ScheduledThreadPoolExecutor$ScheduledFutureTask.run(ScheduledThreadPoolExecutor.java:305)
	at java.base/java.util.concurrent.ThreadPoolExecutor.runWorker(ThreadPoolExecutor.java:1136)
	at java.base/java.util.concurrent.ThreadPoolExecutor$Worker.run(ThreadPoolExecutor.java:635)
	at java.base/java.lang.Thread.run(Thread.java:842)
2025-01-13 17:20:51 [scheduling-1] ERROR p.e.domain.test.testService - test
2025-01-13 17:20:51 [scheduling-1] ERROR o.s.s.s.TaskUtils$LoggingErrorHandler - Unexpected error occurred in scheduled task
practice.error_exception.global.exception.object.ServiceException: TEST
	at practice.error_exception.domain.test.testService.logTest(testService.java:17)
	at java.base/jdk.internal.reflect.NativeMethodAccessorImpl.invoke0(Native Method)
	at java.base/jdk.internal.reflect.NativeMethodAccessorImpl.invoke(NativeMethodAccessorImpl.java:77)
	at java.base/jdk.internal.reflect.DelegatingMethodAccessorImpl.invoke(DelegatingMethodAccessorImpl.java:43)
	at java.base/java.lang.reflect.Method.invoke(Method.java:568)
	at org.springframework.scheduling.support.ScheduledMethodRunnable.runInternal(ScheduledMethodRunnable.java:130)
	at org.springframework.scheduling.support.ScheduledMethodRunnable.lambda$run$2(ScheduledMethodRunnable.java:124)
	at io.micrometer.observation.Observation.observe(Observation.java:498)
	at org.springframework.scheduling.support.ScheduledMethodRunnable.run(ScheduledMethodRunnable.java:124)
	at org.springframework.scheduling.config.Task$OutcomeTrackingRunnable.run(Task.java:85)
	at org.springframework.scheduling.support.DelegatingErrorHandlingRunnable.run(DelegatingErrorHandlingRunnable.java:54)
	at java.base/java.util.concurrent.Executors$RunnableAdapter.call(Executors.java:539)
	at java.base/java.util.concurrent.FutureTask.runAndReset(FutureTask.java:305)
	at java.base/java.util.concurrent.ScheduledThreadPoolExecutor$ScheduledFutureTask.run(ScheduledThreadPoolExecutor.java:305)
	at java.base/java.util.concurrent.ThreadPoolExecutor.runWorker(ThreadPoolExecutor.java:1136)
	at java.base/java.util.concurrent.ThreadPoolExecutor$Worker.run(ThreadPoolExecutor.java:635)
	at java.base/java.lang.Thread.run(Thread.java:842)
2025-01-13 17:21:01 [scheduling-1] ERROR p.e.domain.test.testService - test
2025-01-13 17:21:01 [scheduling-1] ERROR o.s.s.s.TaskUtils$LoggingErrorHandler - Unexpected error occurred in scheduled task
practice.error_exception.global.exception.object.ServiceException: TEST
	at practice.error_exception.domain.test.testService.logTest(testService.java:17)
	at java.base/jdk.internal.reflect.NativeMethodAccessorImpl.invoke0(Native Method)
	at java.base/jdk.internal.reflect.NativeMethodAccessorImpl.invoke(NativeMethodAccessorImpl.java:77)
	at java.base/jdk.internal.reflect.DelegatingMethodAccessorImpl.invoke(DelegatingMethodAccessorImpl.java:43)
	at java.base/java.lang.reflect.Method.invoke(Method.java:568)
	at org.springframework.scheduling.support.ScheduledMethodRunnable.runInternal(ScheduledMethodRunnable.java:130)
	at org.springframework.scheduling.support.ScheduledMethodRunnable.lambda$run$2(ScheduledMethodRunnable.java:124)
	at io.micrometer.observation.Observation.observe(Observation.java:498)
	at org.springframework.scheduling.support.ScheduledMethodRunnable.run(ScheduledMethodRunnable.java:124)
	at org.springframework.scheduling.config.Task$OutcomeTrackingRunnable.run(Task.java:85)
	at org.springframework.scheduling.support.DelegatingErrorHandlingRunnable.run(DelegatingErrorHandlingRunnable.java:54)
	at java.base/java.util.concurrent.Executors$RunnableAdapter.call(Executors.java:539)
	at java.base/java.util.concurrent.FutureTask.runAndReset(FutureTask.java:305)
	at java.base/java.util.concurrent.ScheduledThreadPoolExecutor$ScheduledFutureTask.run(ScheduledThreadPoolExecutor.java:305)
	at java.base/java.util.concurrent.ThreadPoolExecutor.runWorker(ThreadPoolExecutor.java:1136)
	at java.base/java.util.concurrent.ThreadPoolExecutor$Worker.run(ThreadPoolExecutor.java:635)
	at java.base/java.lang.Thread.run(Thread.java:842)
2025-01-13 17:34:02 [taskScheduler-1] ERROR p.e.domain.test.testService - test
2025-01-13 17:34:02 [taskScheduler-1] ERROR p.e.g.e.handler.CustomErrorHandler - Service error occurred: TEST
practice.error_exception.global.exception.object.ServiceException: TEST
	at practice.error_exception.domain.test.testService.logTest(testService.java:17)
	at java.base/jdk.internal.reflect.NativeMethodAccessorImpl.invoke0(Native Method)
	at java.base/jdk.internal.reflect.NativeMethodAccessorImpl.invoke(NativeMethodAccessorImpl.java:77)
	at java.base/jdk.internal.reflect.DelegatingMethodAccessorImpl.invoke(DelegatingMethodAccessorImpl.java:43)
	at java.base/java.lang.reflect.Method.invoke(Method.java:568)
	at org.springframework.scheduling.support.ScheduledMethodRunnable.runInternal(ScheduledMethodRunnable.java:130)
	at org.springframework.scheduling.support.ScheduledMethodRunnable.lambda$run$2(ScheduledMethodRunnable.java:124)
	at io.micrometer.observation.Observation.observe(Observation.java:498)
	at org.springframework.scheduling.support.ScheduledMethodRunnable.run(ScheduledMethodRunnable.java:124)
	at org.springframework.scheduling.config.Task$OutcomeTrackingRunnable.run(Task.java:85)
	at org.springframework.scheduling.support.DelegatingErrorHandlingRunnable.run(DelegatingErrorHandlingRunnable.java:54)
	at java.base/java.util.concurrent.Executors$RunnableAdapter.call(Executors.java:539)
	at java.base/java.util.concurrent.FutureTask.runAndReset(FutureTask.java:305)
	at java.base/java.util.concurrent.ScheduledThreadPoolExecutor$ScheduledFutureTask.run(ScheduledThreadPoolExecutor.java:305)
	at java.base/java.util.concurrent.ThreadPoolExecutor.runWorker(ThreadPoolExecutor.java:1136)
	at java.base/java.util.concurrent.ThreadPoolExecutor$Worker.run(ThreadPoolExecutor.java:635)
	at java.base/java.lang.Thread.run(Thread.java:842)
2025-01-13 17:34:02 [taskScheduler-1] ERROR p.e.g.e.handler.CustomErrorHandler - Exception type: practice.error_exception.global.exception.object.ServiceException
2025-01-13 17:34:12 [taskScheduler-1] ERROR p.e.domain.test.testService - test
2025-01-13 17:34:12 [taskScheduler-1] ERROR p.e.g.e.handler.CustomErrorHandler - Service error occurred: TEST
practice.error_exception.global.exception.object.ServiceException: TEST
	at practice.error_exception.domain.test.testService.logTest(testService.java:17)
	at java.base/jdk.internal.reflect.NativeMethodAccessorImpl.invoke0(Native Method)
	at java.base/jdk.internal.reflect.NativeMethodAccessorImpl.invoke(NativeMethodAccessorImpl.java:77)
	at java.base/jdk.internal.reflect.DelegatingMethodAccessorImpl.invoke(DelegatingMethodAccessorImpl.java:43)
	at java.base/java.lang.reflect.Method.invoke(Method.java:568)
	at org.springframework.scheduling.support.ScheduledMethodRunnable.runInternal(ScheduledMethodRunnable.java:130)
	at org.springframework.scheduling.support.ScheduledMethodRunnable.lambda$run$2(ScheduledMethodRunnable.java:124)
	at io.micrometer.observation.Observation.observe(Observation.java:498)
	at org.springframework.scheduling.support.ScheduledMethodRunnable.run(ScheduledMethodRunnable.java:124)
	at org.springframework.scheduling.config.Task$OutcomeTrackingRunnable.run(Task.java:85)
	at org.springframework.scheduling.support.DelegatingErrorHandlingRunnable.run(DelegatingErrorHandlingRunnable.java:54)
	at java.base/java.util.concurrent.Executors$RunnableAdapter.call(Executors.java:539)
	at java.base/java.util.concurrent.FutureTask.runAndReset(FutureTask.java:305)
	at java.base/java.util.concurrent.ScheduledThreadPoolExecutor$ScheduledFutureTask.run(ScheduledThreadPoolExecutor.java:305)
	at java.base/java.util.concurrent.ThreadPoolExecutor.runWorker(ThreadPoolExecutor.java:1136)
	at java.base/java.util.concurrent.ThreadPoolExecutor$Worker.run(ThreadPoolExecutor.java:635)
	at java.base/java.lang.Thread.run(Thread.java:842)
2025-01-13 17:34:12 [taskScheduler-1] ERROR p.e.g.e.handler.CustomErrorHandler - Exception type: practice.error_exception.global.exception.object.ServiceException
2025-01-13 17:34:22 [taskScheduler-2] ERROR p.e.domain.test.testService - test
2025-01-13 17:34:22 [taskScheduler-2] ERROR p.e.g.e.handler.CustomErrorHandler - Service error occurred: TEST
practice.error_exception.global.exception.object.ServiceException: TEST
	at practice.error_exception.domain.test.testService.logTest(testService.java:17)
	at java.base/jdk.internal.reflect.NativeMethodAccessorImpl.invoke0(Native Method)
	at java.base/jdk.internal.reflect.NativeMethodAccessorImpl.invoke(NativeMethodAccessorImpl.java:77)
	at java.base/jdk.internal.reflect.DelegatingMethodAccessorImpl.invoke(DelegatingMethodAccessorImpl.java:43)
	at java.base/java.lang.reflect.Method.invoke(Method.java:568)
	at org.springframework.scheduling.support.ScheduledMethodRunnable.runInternal(ScheduledMethodRunnable.java:130)
	at org.springframework.scheduling.support.ScheduledMethodRunnable.lambda$run$2(ScheduledMethodRunnable.java:124)
	at io.micrometer.observation.Observation.observe(Observation.java:498)
	at org.springframework.scheduling.support.ScheduledMethodRunnable.run(ScheduledMethodRunnable.java:124)
	at org.springframework.scheduling.config.Task$OutcomeTrackingRunnable.run(Task.java:85)
	at org.springframework.scheduling.support.DelegatingErrorHandlingRunnable.run(DelegatingErrorHandlingRunnable.java:54)
	at java.base/java.util.concurrent.Executors$RunnableAdapter.call(Executors.java:539)
	at java.base/java.util.concurrent.FutureTask.runAndReset(FutureTask.java:305)
	at java.base/java.util.concurrent.ScheduledThreadPoolExecutor$ScheduledFutureTask.run(ScheduledThreadPoolExecutor.java:305)
	at java.base/java.util.concurrent.ThreadPoolExecutor.runWorker(ThreadPoolExecutor.java:1136)
	at java.base/java.util.concurrent.ThreadPoolExecutor$Worker.run(ThreadPoolExecutor.java:635)
	at java.base/java.lang.Thread.run(Thread.java:842)
2025-01-13 17:34:22 [taskScheduler-2] ERROR p.e.g.e.handler.CustomErrorHandler - Exception type: practice.error_exception.global.exception.object.ServiceException
2025-01-13 17:34:32 [taskScheduler-2] ERROR p.e.domain.test.testService - test
2025-01-13 17:34:32 [taskScheduler-2] ERROR p.e.g.e.handler.CustomErrorHandler - Service error occurred: TEST
practice.error_exception.global.exception.object.ServiceException: TEST
	at practice.error_exception.domain.test.testService.logTest(testService.java:17)
	at java.base/jdk.internal.reflect.NativeMethodAccessorImpl.invoke0(Native Method)
	at java.base/jdk.internal.reflect.NativeMethodAccessorImpl.invoke(NativeMethodAccessorImpl.java:77)
	at java.base/jdk.internal.reflect.DelegatingMethodAccessorImpl.invoke(DelegatingMethodAccessorImpl.java:43)
	at java.base/java.lang.reflect.Method.invoke(Method.java:568)
	at org.springframework.scheduling.support.ScheduledMethodRunnable.runInternal(ScheduledMethodRunnable.java:130)
	at org.springframework.scheduling.support.ScheduledMethodRunnable.lambda$run$2(ScheduledMethodRunnable.java:124)
	at io.micrometer.observation.Observation.observe(Observation.java:498)
	at org.springframework.scheduling.support.ScheduledMethodRunnable.run(ScheduledMethodRunnable.java:124)
	at org.springframework.scheduling.config.Task$OutcomeTrackingRunnable.run(Task.java:85)
	at org.springframework.scheduling.support.DelegatingErrorHandlingRunnable.run(DelegatingErrorHandlingRunnable.java:54)
	at java.base/java.util.concurrent.Executors$RunnableAdapter.call(Executors.java:539)
	at java.base/java.util.concurrent.FutureTask.runAndReset(FutureTask.java:305)
	at java.base/java.util.concurrent.ScheduledThreadPoolExecutor$ScheduledFutureTask.run(ScheduledThreadPoolExecutor.java:305)
	at java.base/java.util.concurrent.ThreadPoolExecutor.runWorker(ThreadPoolExecutor.java:1136)
	at java.base/java.util.concurrent.ThreadPoolExecutor$Worker.run(ThreadPoolExecutor.java:635)
	at java.base/java.lang.Thread.run(Thread.java:842)
2025-01-13 17:34:32 [taskScheduler-2] ERROR p.e.g.e.handler.CustomErrorHandler - Exception type: practice.error_exception.global.exception.object.ServiceException
2025-01-13 17:37:53 [taskScheduler-1] ERROR p.e.domain.test.testService - test
2025-01-13 17:37:53 [taskScheduler-1] ERROR p.e.g.e.handler.CustomErrorHandler - Service error occurred: TEST
2025-01-13 17:38:03 [taskScheduler-1] ERROR p.e.domain.test.testService - test
2025-01-13 17:38:03 [taskScheduler-1] ERROR p.e.g.e.handler.CustomErrorHandler - Service error occurred: TEST
2025-01-13 17:38:13 [taskScheduler-2] ERROR p.e.domain.test.testService - test
2025-01-13 17:38:13 [taskScheduler-2] ERROR p.e.g.e.handler.CustomErrorHandler - Service error occurred: TEST
2025-01-13 17:38:23 [taskScheduler-2] ERROR p.e.domain.test.testService - test
2025-01-13 17:38:23 [taskScheduler-2] ERROR p.e.g.e.handler.CustomErrorHandler - Service error occurred: TEST
2025-01-13 17:38:33 [taskScheduler-2] ERROR p.e.domain.test.testService - test
2025-01-13 17:38:33 [taskScheduler-2] ERROR p.e.g.e.handler.CustomErrorHandler - Service error occurred: TEST
2025-01-13 17:38:46 [taskScheduler-1] ERROR p.e.domain.test.testService - test
2025-01-13 17:39:36 [taskScheduler-1] ERROR p.e.domain.test.testService - test
2025-01-13 17:39:36 [taskScheduler-1] ERROR p.e.g.e.handler.CustomErrorHandler - Service error occurred: TEST
2025-01-13 17:39:46 [taskScheduler-1] ERROR p.e.domain.test.testService - test
2025-01-13 17:39:46 [taskScheduler-1] ERROR p.e.g.e.handler.CustomErrorHandler - Service error occurred: TEST
2025-01-13 17:40:47 [taskScheduler-1] ERROR p.e.domain.test.testService - test
2025-01-13 17:40:47 [taskScheduler-1] ERROR p.e.g.e.handler.CustomErrorHandler - Unexpected error occurred: TEST
practice.error_exception.global.exception.object.ServiceException: TEST
	at practice.error_exception.domain.test.testService.logTest(testService.java:17)
	at java.base/jdk.internal.reflect.NativeMethodAccessorImpl.invoke0(Native Method)
	at java.base/jdk.internal.reflect.NativeMethodAccessorImpl.invoke(NativeMethodAccessorImpl.java:77)
	at java.base/jdk.internal.reflect.DelegatingMethodAccessorImpl.invoke(DelegatingMethodAccessorImpl.java:43)
	at java.base/java.lang.reflect.Method.invoke(Method.java:568)
	at org.springframework.scheduling.support.ScheduledMethodRunnable.runInternal(ScheduledMethodRunnable.java:130)
	at org.springframework.scheduling.support.ScheduledMethodRunnable.lambda$run$2(ScheduledMethodRunnable.java:124)
	at io.micrometer.observation.Observation.observe(Observation.java:498)
	at org.springframework.scheduling.support.ScheduledMethodRunnable.run(ScheduledMethodRunnable.java:124)
	at org.springframework.scheduling.config.Task$OutcomeTrackingRunnable.run(Task.java:85)
	at org.springframework.scheduling.support.DelegatingErrorHandlingRunnable.run(DelegatingErrorHandlingRunnable.java:54)
	at java.base/java.util.concurrent.Executors$RunnableAdapter.call(Executors.java:539)
	at java.base/java.util.concurrent.FutureTask.runAndReset(FutureTask.java:305)
	at java.base/java.util.concurrent.ScheduledThreadPoolExecutor$ScheduledFutureTask.run(ScheduledThreadPoolExecutor.java:305)
	at java.base/java.util.concurrent.ThreadPoolExecutor.runWorker(ThreadPoolExecutor.java:1136)
	at java.base/java.util.concurrent.ThreadPoolExecutor$Worker.run(ThreadPoolExecutor.java:635)
	at java.base/java.lang.Thread.run(Thread.java:842)
2025-01-13 17:40:58 [taskScheduler-1] ERROR p.e.domain.test.testService - test
2025-01-13 17:40:58 [taskScheduler-1] ERROR p.e.g.e.handler.CustomErrorHandler - Unexpected error occurred: TEST
practice.error_exception.global.exception.object.ServiceException: TEST
	at practice.error_exception.domain.test.testService.logTest(testService.java:17)
	at java.base/jdk.internal.reflect.NativeMethodAccessorImpl.invoke0(Native Method)
	at java.base/jdk.internal.reflect.NativeMethodAccessorImpl.invoke(NativeMethodAccessorImpl.java:77)
	at java.base/jdk.internal.reflect.DelegatingMethodAccessorImpl.invoke(DelegatingMethodAccessorImpl.java:43)
	at java.base/java.lang.reflect.Method.invoke(Method.java:568)
	at org.springframework.scheduling.support.ScheduledMethodRunnable.runInternal(ScheduledMethodRunnable.java:130)
	at org.springframework.scheduling.support.ScheduledMethodRunnable.lambda$run$2(ScheduledMethodRunnable.java:124)
	at io.micrometer.observation.Observation.observe(Observation.java:498)
	at org.springframework.scheduling.support.ScheduledMethodRunnable.run(ScheduledMethodRunnable.java:124)
	at org.springframework.scheduling.config.Task$OutcomeTrackingRunnable.run(Task.java:85)
	at org.springframework.scheduling.support.DelegatingErrorHandlingRunnable.run(DelegatingErrorHandlingRunnable.java:54)
	at java.base/java.util.concurrent.Executors$RunnableAdapter.call(Executors.java:539)
	at java.base/java.util.concurrent.FutureTask.runAndReset(FutureTask.java:305)
	at java.base/java.util.concurrent.ScheduledThreadPoolExecutor$ScheduledFutureTask.run(ScheduledThreadPoolExecutor.java:305)
	at java.base/java.util.concurrent.ThreadPoolExecutor.runWorker(ThreadPoolExecutor.java:1136)
	at java.base/java.util.concurrent.ThreadPoolExecutor$Worker.run(ThreadPoolExecutor.java:635)
	at java.base/java.lang.Thread.run(Thread.java:842)
2025-01-13 17:42:04 [taskScheduler-1] ERROR p.e.domain.test.testService - test
2025-01-13 17:42:04 [taskScheduler-1] ERROR p.e.g.e.handler.CustomErrorHandler - Service error occurred: practice.error_exception.global.exception.object.ServiceException
2025-01-13 17:42:14 [taskScheduler-1] ERROR p.e.domain.test.testService - test
2025-01-13 17:42:14 [taskScheduler-1] ERROR p.e.g.e.handler.CustomErrorHandler - Service error occurred: practice.error_exception.global.exception.object.ServiceException
2025-01-13 17:43:12 [taskScheduler-1] ERROR p.e.domain.test.testService - test
2025-01-13 17:43:12 [taskScheduler-1] ERROR p.e.g.e.handler.CustomErrorHandler - Service error occurred: practice.error_exception.global.exception.object.ServiceException
2025-01-13 17:43:12 [taskScheduler-1] ERROR p.e.g.e.handler.CustomErrorHandler - Error Message: TEST
2025-01-13 17:46:39 [taskScheduler-1] ERROR p.e.domain.test.testService - test
2025-01-13 17:46:39 [taskScheduler-1] ERROR p.e.g.e.handler.CustomErrorHandler - Unexpected error occurred: java.lang.NullPointerException
2025-01-13 17:46:39 [taskScheduler-1] ERROR p.e.g.e.handler.CustomErrorHandler - Error Message: null
2025-01-13 17:46:49 [taskScheduler-1] ERROR p.e.domain.test.testService - test
2025-01-13 17:46:49 [taskScheduler-1] ERROR p.e.g.e.handler.CustomErrorHandler - Unexpected error occurred: java.lang.NullPointerException
2025-01-13 17:46:49 [taskScheduler-1] ERROR p.e.g.e.handler.CustomErrorHandler - Error Message: null
2025-01-13 17:47:05 [taskScheduler-1] ERROR p.e.domain.test.testService - test
2025-01-13 17:47:05 [taskScheduler-1] ERROR p.e.g.e.handler.CustomErrorHandler - Unexpected error occurred: java.lang.NullPointerException
2025-01-13 17:47:05 [taskScheduler-1] ERROR p.e.g.e.handler.CustomErrorHandler - Error Message: null
2025-01-13 17:47:56 [taskScheduler-1] ERROR p.e.domain.test.testService - test
2025-01-13 17:48:29 [taskScheduler-1] ERROR p.e.domain.test.testService - test
2025-01-13 17:48:29 [taskScheduler-1] ERROR p.e.g.e.handler.CustomErrorHandler - Unexpected error occurred: java.lang.NullPointerException
2025-01-13 17:48:29 [taskScheduler-1] ERROR p.e.g.e.handler.CustomErrorHandler - Error Message: Cannot invoke "String.toString()" because "s" is null
2025-01-13 17:56:08 [taskScheduler-1] ERROR p.e.domain.test.testService - test
2025-01-13 17:56:08 [taskScheduler-1] ERROR p.e.g.e.handler.CustomErrorHandler - Service error occurred: practice.error_exception.global.exception.handler.testHandler
2025-01-13 17:56:08 [taskScheduler-1] ERROR p.e.g.e.handler.CustomErrorHandler - Error Message: test
